Found 3287 files belonging to 4 classes.
Using 2137 files for training.
Using 1150 files for validation.
FINISHED LOADING DATA
FINISHED INITIALIZING CALLBACKS
FINISHED COMPILING MODEL
Epoch 1/30
Traceback (most recent call last):
  File "/scratch/st-sielmann-1/agrobot/grape-ld/__main__.py", line 128, in <module>
    history = model.fit(
  File "/home/nlin06/miniconda3/envs/grape-ld/lib/python3.10/site-packages/keras/src/utils/traceback_utils.py", line 70, in error_handler
    raise e.with_traceback(filtered_tb) from None
  File "/tmp/__autograph_generated_filei0iidy4q.py", line 15, in tf__train_function
    retval_ = ag__.converted_call(ag__.ld(step_function), (ag__.ld(self), ag__.ld(iterator)), None, fscope)
ValueError: in user code:
    File "/home/nlin06/miniconda3/envs/grape-ld/lib/python3.10/site-packages/keras/src/engine/training.py", line 1401, in train_function  *
        return step_function(self, iterator)
    File "/home/nlin06/miniconda3/envs/grape-ld/lib/python3.10/site-packages/keras/src/engine/training.py", line 1384, in step_function  **
        outputs = model.distribute_strategy.run(run_step, args=(data,))
    File "/home/nlin06/miniconda3/envs/grape-ld/lib/python3.10/site-packages/keras/src/engine/training.py", line 1373, in run_step  **
        outputs = model.train_step(data)
    File "/home/nlin06/miniconda3/envs/grape-ld/lib/python3.10/site-packages/keras/src/engine/training.py", line 1151, in train_step
        loss = self.compute_loss(x, y, y_pred, sample_weight)
    File "/home/nlin06/miniconda3/envs/grape-ld/lib/python3.10/site-packages/keras/src/engine/training.py", line 1209, in compute_loss
        return self.compiled_loss(
    File "/home/nlin06/miniconda3/envs/grape-ld/lib/python3.10/site-packages/keras/src/engine/compile_utils.py", line 277, in __call__
        loss_value = loss_obj(y_t, y_p, sample_weight=sw)
    File "/home/nlin06/miniconda3/envs/grape-ld/lib/python3.10/site-packages/keras/src/losses.py", line 143, in __call__
        losses = call_fn(y_true, y_pred)
    File "/home/nlin06/miniconda3/envs/grape-ld/lib/python3.10/site-packages/keras/src/losses.py", line 270, in call  **
        return ag_fn(y_true, y_pred, **self._fn_kwargs)
    File "/home/nlin06/miniconda3/envs/grape-ld/lib/python3.10/site-packages/keras/src/losses.py", line 2221, in categorical_crossentropy
        return backend.categorical_crossentropy(
    File "/home/nlin06/miniconda3/envs/grape-ld/lib/python3.10/site-packages/keras/src/backend.py", line 5573, in categorical_crossentropy
        target.shape.assert_is_compatible_with(output.shape)
    ValueError: Shapes (None, 4) and (None, 6, 6, 4) are incompatible