Found 3287 files belonging to 4 classes.
Using 2137 files for training.
Using 1150 files for validation.
FINISHED LOADING DATA
FINISHED INITIALIZING CALLBACKS
FINISHED COMPILING MODEL
Epoch 1/30
Traceback (most recent call last):
  File "/scratch/st-sielmann-1/agrobot/grape-ld/__main__.py", line 129, in <module>
    history = model.fit(
  File "/home/nlin06/miniconda3/envs/grape-ld/lib/python3.10/site-packages/keras/src/utils/traceback_utils.py", line 70, in error_handler
    raise e.with_traceback(filtered_tb) from None
  File "/tmp/__autograph_generated_filem7qd4_73.py", line 15, in tf__train_function
    retval_ = ag__.converted_call(ag__.ld(step_function), (ag__.ld(self), ag__.ld(iterator)), None, fscope)
ValueError: in user code:
    File "/home/nlin06/miniconda3/envs/grape-ld/lib/python3.10/site-packages/keras/src/engine/training.py", line 1401, in train_function  *
        return step_function(self, iterator)
    File "/home/nlin06/miniconda3/envs/grape-ld/lib/python3.10/site-packages/keras/src/engine/training.py", line 1384, in step_function  **
        outputs = model.distribute_strategy.run(run_step, args=(data,))
    File "/home/nlin06/miniconda3/envs/grape-ld/lib/python3.10/site-packages/keras/src/engine/training.py", line 1373, in run_step  **
        outputs = model.train_step(data)
    File "/home/nlin06/miniconda3/envs/grape-ld/lib/python3.10/site-packages/keras/src/engine/training.py", line 1150, in train_step
        y_pred = self(x, training=True)
    File "/home/nlin06/miniconda3/envs/grape-ld/lib/python3.10/site-packages/keras/src/utils/traceback_utils.py", line 70, in error_handler
        raise e.with_traceback(filtered_tb) from None
    File "/home/nlin06/miniconda3/envs/grape-ld/lib/python3.10/site-packages/keras/src/engine/input_spec.py", line 298, in assert_input_compatibility
        raise ValueError(
    ValueError: Input 0 of layer "model" is incompatible with the layer: expected shape=(None, 1, 1, 3), found shape=(None, 256, 256, 3)